Workbook

Sheet Dashboard
A1: NEOPRO SAFe Portfolio Dashboard
A3: PORTFOLIO OVERVIEW
A4: Epics | B4: =COUNTA('Epics & LBC'!A4:A24)-COUNTBLANK('Epics & LBC'!A4:A24) | C4: Features | D4: =COUNTA('Features & US'!B5:B41)-COUNTBLANK('Features & US'!B5:B41) | E4: User Stories | F4: =SUM('Features & US'!D5:D41) | G4: Total SP | H4: =SUM('Features & US'!E5:E41)
A5: SP PI-1 | B5: =SUMIF('Features & US'!I:I,"PI-1*",'Features & US'!E:E) | C5: SP PI-2 | D5: =SUMIF('Features & US'!I:I,"PI-2*",'Features & US'!E:E) | E5: SP PI-3 | F5: =SUMIF('Features & US'!I:I,"PI-3*",'Features & US'!E:E) | G5: ARR (K€) | H5: 350
A7: EPICS STATUS | C7: FEATURES STATUS | E7: RISKS (ROAM) | G7: FLOW DISTRIBUTION
A8: En cours | B8: =COUNTIF('Epics & LBC'!G:G,"En cours") | C8: Terminé | D8: =COUNTIF('Features & US'!G5:G41,"Terminé") | E8: Open | F8: =COUNTIF(ROAM!C:C,"Owned")+COUNTIF(ROAM!C:C,"Accepted") | G8: Monétisation | H8: 0.4
A9: Terminé | B9: =COUNTIF('Epics & LBC'!G:G,"Terminé") | C9: Backlog | D9: =COUNTIF('Features & US'!G5:G41,"Backlog") | E9: Resolved | F9: =COUNTIF(ROAM!C:C,"Resolved")+COUNTIF(ROAM!C:C,"Mitigated") | G9: Exp. Match | H9: 0.25
A10: Backlog | B10: =COUNTIF('Epics & LBC'!G:G,"Backlog") | C10: En cours | D10: =COUNTIF('Features & US'!G5:G41,"En cours") | E10: Owned | F10: =COUNTIF(ROAM!C:C,"Owned") | G10: Acquisition | H10: 0.2
A11: Total | B11: =B8+B9+B10 | C11: Total | D11: =D8+D9+D10 | E11: Excellence Ops | G11: Excellence Ops | H11: 0.15
A13: ROADMAP SUMMARY
A14: PI | B14: Période | C14: Initiatives clés | G14: Planned SP | H14: Status
A15: PI-1 | B15: Fév-Mar | C15: Sponsors + Analytics + Onboarding + Résilience WiFi | G15: =SUMIF('Features & US'!I:I,"PI-1*",'Features & US'!E:E) | H15: 🟢 Active
A16: PI-2 | B16: Avr-Mai | C16: Régie + Motion + Email + Score API Fédérations | G16: =SUMIF('Features & US'!I:I,"PI-2*",'Features & US'!E:E) | H16: 🟡 Planned
A17: PI-3 | B17: Jun-Jul | C17: Multi-écrans + Marque blanche + Billetterie + ML + OAuth | G17: =SUMIF('Features & US'!I:I,"PI-3*",'Features & US'!E:E) | H17: ⚪ Backlog
A19: SPRINT VELOCITY (PI-1)
A20: Sprint | B20: S1 | C20: S2 | D20: S3 | E20: S4 | F20: S5 | G20: S6 | H20: Avg
A21: Actual SP | B21: ='Sprint Tracker'!D6 | C21: ='Sprint Tracker'!D7 | D21: ='Sprint Tracker'!D8 | E21: ='Sprint Tracker'!D9 | F21: =IF('Sprint Tracker'!D10="","-",'Sprint Tracker'!D10) | G21: =IF('Sprint Tracker'!D11="","-",'Sprint Tracker'!D11) | H21: =IFERROR(AVERAGE('Sprint Tracker'!D6:D9),0)
A23: NAVIGATION
A24: Vision & OKR | B24: Value Streams | C24: Epics & LBC | D24: Features & US | E24: PI Objectives | F24: Sprint Tracker | G24: ROAM | H24: Flow Metrics
A25: Glossaire | B25: Impl. Backlog
A27: CHARTS

Sheet Glossaire
A1: Glossaire SAFe pour Gabin
A2: Terme | B2: Définition
A3: Epic | B3: Grande initiative couvrant plusieurs Features, liée à une stratégie business
A4: Feature | B4: Bloc fonctionnel apportant valeur, découpé en User Stories
A5: User Story | B5: Récit utilisateur livrable en 1-2 sprints (taille ~5 SP)
A6: Story Point (SP) | B6: Unité de complexité relative (Fibonacci: 1,2,3,5,8...)
A7: Sprint | B7: Itération 2 semaines de travail continu
A8: PI (Program Increment) | B8: Trim de 3 mois = 6 sprints alignés
A9: Value Stream | B9: Flux continu de création de valeur (OVS ou DVS)
A10: WSJF (Weighted Shortest Job First) | B10: Priorisation: (User-Biz-Time-RR) / Job Size
A11: MoSCoW | B11: Must (obligatoire), Should (important), Could (sympa), Won't (exclu)
A12: Lean Business Case | B12: Justification business simplifiée (coût vs bénéfice)
A13: Critères d'acceptation | B13: Conditions pour que la US soit "Done" (définition
... A25: I&A (Inspect & Adapt) | B25: Rétrospective SAFe collective tous les PIs

Sheet Vision & OKR
A1: NEOPRO — Vision, Thèmes Stratégiques & OKR 2026
A3: Vision Produit
A5: Devenir le partenaire de référence des clubs sportifs amateurs en France pour promouvoir leur identité, engager leurs communautés et monétiser leur audience via une solution TV interactive clé-en-main.
A7: 4 Thèmes Stratégiques
A8: ID | B8: Thème | C8: Description | D8: OVS lié | E8: Horizon | F8: Poids budget
A9: TS-1 | B9: Monétisation Sponsors | C9: Maximiser les revenus sponsors par club via le ciblage local, les preuves de diffusion et le self-service | D9: OVS-2 | E9: PI-1 → PI-3 | F9: 35%
A10: TS-2 | B10: Expérience Match Live | C10: Offrir la meilleure expérience match jour (overlay multi-sport, timer, recording) | D10: OVS-1 | E10: PI-1 → PI-2 | F10: 25%
A11: TS-3 | B11: Acquisition & Croissance | C11: Accélérer l'onboarding clubs (time-to-value <1j), réduire le churn (<5%/an), atteindre 100 clubs | D11: OVS-1 + OVS-2 | E11: PI-2 → PI-3 | F11: 20%
A12: TS-4 | B12: Excellence Opérationnelle | C12: Garantir 99.5% uptime, <2h MTTR, monitoring proactif, OTA fiable, réseau résilient | D12: DVS-1 | E12: Continu | F12: 20%
A14: OKR 2026 — Objectifs & Key Results
A15: Obj # | B15: Objectif | C15: KR # | D15: Key Result | E15: Thème(s) | F15: Target
A16: O1 | B16: Faire de NEOPRO le partenaire de référence des clubs amateurs en Bretagne/Pays de Loire | C16: 1.1 | D16: 3 clubs beta convertis en payants | E16: TS-3 | F16: Q2 2026
C17: 1.2 | D17: 15 clubs payants actifs | E17: TS-3 | F17: Déc 2026
C18: 1.3 | D18: Taux de renouvellement >85% | E18: TS-3 | F18: Déc 2026
C19: 1.4 | D19: NPS clubs ≥8/10 | E19: TS-2, TS-3 | F19: Q4 2026
C20: 1.5 | D20: 2 partenariats ligues régionales signés | E20: TS-3 | F20: Q3 2026
C21: 1.6 | D21: 3 cas ROI sponsors documentés | E21: TS-1 | F21: Q3 2026
C22: 1.7 | D22: 6 annonceurs régionaux actifs | E22: TS-1 | F22: Q4 2026
C23: 1.8 | D23: ARPU annonceur >200€/mois | E23: TS-1 | F23: Q4 2026
A24: O2 | B24: Créer une expérience match que les clubs ne peuvent plus quitter | C24: 2.1 | D24: Taux d'utilisation 100% des matchs à domicile | E24: TS-2 | F24: Q4 2026
C25: 2.2 | D25: Latence télécommande <200ms local / <2s cloud | E25: TS-2 | F25: Q1 2026
C26: 2.3 | D26: 6 sports supportés en overlay | E26: TS-2 | F26: ✅ Done
C27: 2.4 | D27: Score CSAT bénévole >4.5/5 | E27: TS-2 | F27: Q3 2026
C28: 2.5 | D28: Taux activation >80% (1er match dans les 7 jours) | E28: TS-2, TS-3 | F28: Continu
C29: 2.6 | D29: 0 incident bloquant pendant un match | E29: TS-2, TS-4 | F29: Continu
C30: 2.7 | D30: Temps d'installation <4h par club | E30: TS-2, TS-4 | F30: Q2 2026
A31: O3 | B31: Bâtir un réseau de clubs qui tire la croissance | C31: 3.1 | D31: 30% des nouveaux clubs via referral | E31: TS-3 | F31: Q4 2026
C32: 3.2 | D32: 10 témoignages vidéo clubs | E32: TS-3 | F32: Q3 2026
C33: 3.3 | D33: 2 clubs ambassadeurs officiels par région | E33: TS-3 | F33: Q4 2026
C34: 3.4 | D34: 15 prospects qualifiés via réseau | E34: TS-3 | F34: Q3 2026
C35: 3.5 | D35: Présence dans 2 médias sportifs régionaux | E35: TS-3 | F35: Q3 2026
C36: 3.6 | D36: 1 partenariat tournoi majeur | E36: TS-3 | F36: Q4 2026
C37: 3.7 | D37: NPS ≥50 | E37: TS-3 | F37: Q4 2026
C38: 3.8 | D38: 25 clubs onboardés en Q1-Q2 | E38: TS-3 | F38: Juin 2026
A39: O4 | B39: Garantir une infrastructure fiable à la hauteur de l'ambition | C39: 4.1 | D39: Uptime API 99.5% | E39: TS-4 | F39: Continu
C40: 4.2 | D40: MTTR incident <2h | E40: TS-4 | F40: Continu
C41: 4.3 | D41: 0 perte de données vidéo/config (checksum SHA-256) | E41: TS-4 | F41: Continu
C42: 4.4 | D42: OTA success rate >95% | E42: TS-4 | F42: Q2 2026
C43: 4.5 | D43: Temps de résolution support <24h | E43: TS-4 | F43: Continu
C44: 4.6 | D44: Monitoring proactif en place (alertes automatiques) | E44: TS-4 | F44: Q2 2026
...

Sheet Value Streams
A1: NEOPRO — Value Streams & Flux de Valeur
A3: Outcome Value Streams (OVS)
A4: ID | B4: Value Stream | C4: Trigger | D4: Value Delivered | E4: Key Steps | F4: Lead Time | G4: Bottleneck
A5: OVS-1 | B5: Club to Screen | C5: Club signe contrat | D5: Vidéos diffusées sur TV dans le gymnase | E5: Onboarding → Config → Upload → Deploy → Diffusion | F5: < 1 jour (target) | G5: Installation physique Pi
A6: OVS-2 | B6: Sponsor to Impression | C6: Annonceur signe contrat | D6: Impressions pub mesurées et certifiées | E6: Signup → Upload pub → Association sites → Diffusion → Report | F6: < 2 jours | G6: Association manuelle site-sponsor
A8: OVS-1 — Club to Screen (détail)
A9: # | B9: Step | C9: Outil | D9: Owner | E9: Durée | F9: Input | G9: Output
A10: 1 | B10: Vente & signature | C10: CRM (externe) | D10: Commercial | E10: 1-2 semaines | F10: Lead club | G10: Contrat signé + abonnement
A11: 2 | B11: Installation Pi dans le club | C11: Toolbox Déploiement | D11: Technicien | E11: 1-2 heures | F11: Pi + TV + SD card | G11: Pi connecté au Dashboard
A12: 3 | B12: Configuration club | C12: Dashboard Admin | D12: Opérateur | E12: 15 min | F12: Logo, catégories, sponsors | G12: Config déployée sur Pi
A13: 4 | B13: Upload vidéos contenu | C13: Dashboard Admin | D13: Opérateur | E13: 10 min | F13: Fichiers vidéo | G13: Vidéos sur FTP + checksum
A14: 5 | B14: Déploiement vers Pi | C14: Central Server → Sync Agent | D14: Automatisé | E14: 2-5 min | F14: Commande deploy | G14: Vidéos sur disque Pi
A15: 6 | B15: Diffusion sur TV | C15: TV Player | D15: Automatisé | E15: Immédiat | F15: Config + vidéos | G15: Boucle vidéo diffusée
A16: 7 | B16: Match day (bénévole) | C16: Télécommande | D16: Staff club | E16: Durée match | F16: QR code / URL | G16: Score live + phases + recording
A17: 8 | B17: Analytics & rapports | C17: Dashboard + PDF | D17: Automatisé | E17: Quotidien | F17: Impressions brutes | G17: Stats club + sponsor
A19: OVS-2 — Sponsor to Impression (détail)
A20: # | B20: Step | C20: Outil | D20: Owner | E20: Durée | F20: Input | G20: Output
A21: 1 | B21: Inscription annonceur | C21: Portail Annonceur / Magic Link | D21: Annonceur | E21: 5 min | F21: Email + vidéo pub | G21: Compte créé + vidéo uploadée
A22: 2 | B22: Association site-sponsor | C22: Dashboard Admin | D22: Opérateur | E22: 2 min | F22: Sponsor + sites cibles | G22: Mapping sponsor→sites
A23: 3 | B23: Sync sponsors vers Pi | C23: Central Server → Sync Agent | D23: Automatisé | E23: 2-5 min | F23: Config updated | G23: Sponsors sur disque Pi
A24: 4 | B24: Diffusion pub sur TV | C24: TV Player | D24: Automatisé | E24: Immédiat | F24: Boucle vidéo avec pubs | G24: Impressions trackées
A25: 5 | B25: Tracking impressions | C25: TV Player → Sync Agent → API | D25: Automatisé | E25: Batch quotidien | F25: Buffer local Pi | G25: Impressions en DB
A26: 6 | B26: Proof of broadcast | C26: Central Server | D26: Automatisé | E26: Temps réel | F26: Screenshot + timestamp | G26: Preuve certifiée SHA-256
A27: 7 | B27: Rapport annonceur | C27: Portail Annonceur / PDF | D27: Annonceur | E27: Self-service | F27: Stats agrégées | G27: PDF/Excel export
A29: DVS-1 — Neopro Platform (Development Value Stream)
A30: # | B30: Step | C30: Owner | D30: Outils | E30: Métriques | F30: Cadence
A31: 1 | B31: Product Discovery & Backlog | C31: PO (Gwenvael) | D31: SAFe Framework, Notion | E31: WSJF score, backlog depth | F31: Continu
A32: 2 | B32: Architecture & Design | C32: Tech Lead | D32: ADR, TypeScript strict | E32: Design reviews passés | F32: Par feature
A33: 3 | B33: Development (Sprint) | C33: Engineering | D33: Git, ESLint, Repository Pattern | E33: Vélocité SP/sprint, WIP | F33: Sprint 2 semaines
A34: 4 | B34: Testing & QA | C34: Engineering | D34: Jest, Karma, Playwright, Smoke | E34: 2 235 tests, coverage | F34: CI automatique
A35: 5 | B35: Release & OTA | C35: DevOps | D35: Git tags, Railway, FTP, Canary | E35: OTA success rate, rollback | F35: ~2 releases/semaine
A36: 6 | B36: Monitoring & Feedback | C36: Support | D36: Grafana, Prometheus, Slack | E36: Uptime, MTTR, NPS | F36: Continu
A38: Cartographie 12 Outils Neopro
A39: # | B39: Outil | C39: Type | D39: Public | E39: Protocole | F39: VS lié | G39: Features clés
A40: 1 | B40: Dashboard Admin | C40: Produit cloud | D40: Admin, Opérateurs | E40: HTTP + WebSocket | F40: OVS-1, OVS-2 | G40: Fleet mgmt, deploy, analytics, alerting, OTA
A41: 2 | B41: Portail Annonceur | C41: Produit cloud | D41: Annonceurs | E41: HTTP + JWT | F41: OVS-2 | G41: Upload pub, stats impressions, export PDF
A42: 3 | B42: Portail Agence | C42: Produit cloud | D42: Agences pub | E42: HTTP + JWT | F42: OVS-2 | G42: Multi-annonceurs, stats agrégées
A43: 4 | B43: Télécommande | C43: Produit cloud+edge | D43: Staff club | E43: Socket.IO | F43: OVS-1 | G43: Score, phases, timer, recording, vidéos
A44: 5 | B44: TV Player | C44: Produit edge | D44: Spectateurs | E44: Socket.IO local | F44: OVS-1, OVS-2 | G44: Double-buffer, overlay 6 sports, watermark
A45: 6 | B45: Admin Panel Pi | C45: Produit edge | D45: Staff + Tech | E45: HTTP local | F45: OVS-1 | G45: Club/Tech mode, upload local, debug
...

Sheet Epics & LBC
A1: ← Dashboard | B1: ← Dashboard
A3: Epic ID | B3: Name | C3: VS | D3: Theme | E3: WSJF | F3: PI | G3: Status | H3: Cost (SP) | I3: Benefit (€) | J3: Business Value | K3: Time Criticality | L3: Job Size
A4: E-01 | B4: Portail Sponsor Self-Service | C4: VS2 - Sponsor to Impression | D4: TS1 - Monétisation | E4: =IF(L4=0,0,(J4+K4)/L4) | F4: PI-1 | G4: Backlog | H4: =SUMIF('Features & US'!A:A,A4,'Features & US'!E:E) | J4: 5 | K4: 8 | L4: 1
A5: E-02 | B5: Rotation Sponsors | C5: VS2 - Sponsor to Impression | D5: TS1 - Monétisation | E5: =IF(L5=0,0,(J5+K5)/L5) | F5: PI-1 | G5: Backlog | H5: =SUMIF('Features & US'!A:A,A5,'Features & US'!E:E) | J5: 5 | K5: 5 | L5: 1
A6: E-03 | B6: Analytics Sponsors Avancé | C6: VS2 - Sponsor to Impression | D6: TS1 - Monétisation | E6: =IF(L6=0,0,(J6+K6)/L6) | F6: PI-1 | G6: Backlog | H6: =SUMIF('Features & US'!A:A,A6,'Features & US'!E:E) | J6: 8 | K6: 13 | L6: 1
A7: E-04 | B7: Profils Config Match | C7: VS1 - Club to Screen | D7: TS2 - Expérience Match | E7: =IF(L7=0,0,(J7+K7)/L7) | F7: PI-1 | G7: Terminé | H7: =SUMIF('Features & US'!A:A,A7,'Features & US'!E:E) | J7: 3 | K7: 5 | L7: 1
A8: E-06 | B8: Onboarding Automatisé | C8: VS1 - Club to Screen | D8: TS3 - Acquisition | E8: =IF(L8=0,0,(J8+K8)/L8) | F8: PI-1 | G8: Backlog | H8: =SUMIF('Features & US'!A:A,A8,'Features & US'!E:E) | J8: 5 | K8: 8 | L8: 2
A9: E-07 | B9: Résilience WiFi V2 | C9: VS1 - Club to Screen | D9: TS3 - Acquisition | E9: =IF(L9=0,0,(J9+K9)/L9) | F9: PI-1 | G9: En cours | H9: =SUMIF('Features & US'!A:A,A9,'Features & US'!E:E) | J9: 8 | K9: 13 | L9: 1
A10: E-08 | B10: Alertes Prédictives | C10: Transverse | D10: TS4 - Excellence Ops | E10: =IF(L10=0,0,(J10+K10)/L10) | F10: PI-1 | G10: Terminé | H10: =SUMIF('Features & US'!A:A,A10,'Features & US'!E:E) | J10: 5 | K10: 8 | L10: 1
A11: E-09 | B11: Architecture Audit | C11: Transverse | D11: TS4 - Excellence Ops | E11: =IF(L11=0,0,(J11+K11)/L11) | F11: PI-1 | G11: Terminé | H11: =SUMIF('Features & US'!A:A,A11,'Features & US'!E:E) | J11: 5 | K11: 5 | L11: 1
A12: E-10 | B12: Monitoring Fleet | C12: Transverse | D12: TS4 - Excellence Ops | E12: =IF(L12=0,0,(J12+K12)/L12) | F12: PI-1 | G12: En cours | H12: =SUMIF('Features & US'!A:A,A12,'Features & US'!E:E) | J12: 8 | K12: 13 | L12: 2
A13: E-05 | B13: Motion Design Personnalisé | C13: VS2 - Sponsor to Impression | D13: TS2 - Expérience Match | E13: =IF(L13=0,0,(J13+K13)/L13) | F13: PI-2 | G13: Backlog | H13: =SUMIF('Features & US'!A:A,A13,'Features & US'!E:E) | J13: 5 | K13: 5 | L13: 1
A14: E-11 | B14: Régie Publicitaire Régionale | C14: VS2 - Sponsor to Impression | D14: TS1 - Monétisation | E14: =IF(L14=0,0,(J14+K14)/L14) | F14: PI-2 | G14: Backlog | H14: =SUMIF('Features & US'!A:A,A14,'Features & US'!E:E) | J14: 3 | K14: 5 | L14: 1
A15: E-15 | B15: Score en Live Phase 2 (API Fédérations) | C15: VS1 - Club to Screen | D15: TS2 - Expérience Match | E15: =IF(L15=0,0,(J15+K15)/L15) | F15: PI-2 | G15: Backlog | H15: =SUMIF('Features & US'!A:A,A15,'Features & US'!E:E) | J15: 3 | K15: 5 | L15: 1
... A25: E-22 | B25: Contenus Différenciés TV+LED | C25: VS1 - Club to Screen | D25: TS2 - Expérience Match | E25: =IF(L25=0,0,(J25+K25)/L25) | F25: PI-2 | G25: Backlog | H25: =SUMIF('Features & US'!A:A,A25,'Features & US'!E:E) | J25: 4 | K25: 5 | L25: 1

Sheet Features & US
A1: ← Dashboard | B1: ← Dashboard
A3: FEATURE BACKLOG
A4: Epic | B4: Feature ID | C4: Feature | D4: US Count | E4: SP | F4: Priority | G4: Statut | H4: Notes | I4: PI | J4: Sprint
A5: PI-1 (Jan-Mar 2025)
A6: E-01 | B6: F-01.1 | C6: Inscription et profil sponsor | D6: =COUNTIF('User Stories'!B:B,B6) | E6: =SUMIF('User Stories'!B:B,B6,'User Stories'!E:E) | F6: 1 | G6: Backlog | I6: PI-1 (Jan-Mar 2025) | J6: S6
A7: E-01 | B7: F-01.2 | C7: Upload vidéo sponsor | D7: =COUNTIF('User Stories'!B:B,B7) | E7: =SUMIF('User Stories'!B:B,B7,'User Stories'!E:E) | F7: 1 | G7: Backlog | I7: PI-1 (Jan-Mar 2025) | J7: S5
A8: E-01 | B8: F-01.3 | C8: Validation admin des spots | D8: =COUNTIF('User Stories'!B:B,B8) | E8: =SUMIF('User Stories'!B:B,B8,'User Stories'!E:E) | F8: 1 | G8: Backlog | I8: PI-1 (Jan-Mar 2025) | J8: S5
A9: E-02 | B9: F-02.1 | C9: Algorithme de rotation équitable | D9: =COUNTIF('User Stories'!B:B,B9) | E9: =SUMIF('User Stories'!B:B,B9,'User Stories'!E:E) | F9: 1 | G9: Backlog | I9: PI-1 (Jan-Mar 2025) | J9: S5
A10: E-03 | B10: F-03.1 | C10: Dashboard impressions sponsor | D10: =COUNTIF('User Stories'!B:B,B10) | E10: =SUMIF('User Stories'!B:B,B10,'User Stories'!E:E) | F10: 1 | G10: Backlog | I10: PI-1 (Jan-Mar 2025) | J10: S6
A11: E-03 | B11: F-03.2 | C11: Export rapport PDF/CSV | D11: =COUNTIF('User Stories'!B:B,B11) | E11: =SUMIF('User Stories'!B:B,B11,'User Stories'!E:E) | F11: 1 | G11: Backlog | I11: PI-1 (Jan-Mar 2025) | J11: S6
A12: E-04 | B12: F-04.1 | C12: Création de profils prédéfinis | D12: =COUNTIF('User Stories'!B:B,B12) | E12: =SUMIF('User Stories'!B:B,B12,'User Stories'!E:E) | F12: 1 | G12: Terminé | I12: PI-1 (Jan-Mar 2025) | J12: S2
A13: E-04 | B13: F-04.2 | C13: Switch depuis la télécommande | D13: =COUNTIF('User Stories'!B:B,B13) | E13: =SUMIF('User Stories'!B:B,B13,'User Stories'!E:E) | F13: 1 | G13: Terminé | I13: PI-1 (Jan-Mar 2025) | J13: S3
A14: E-05 | B14: F-05.1 | C14: Bibliothèque de templates motion design | D14: =COUNTIF('User Stories'!B:B,B14) | E14: =SUMIF('User Stories'!B:B,B14,'User Stories'!E:E) | F14: 1 | G14: Backlog | I14: PI-1 (Jan-Mar 2025) | J14: S6
A15: E-06 | B15: F-06.1 | C15: Auto-provisioning Pi | D15: =COUNTIF('User Stories'!B:B,B15) | E15: =SUMIF('User Stories'!B:B,B15,'User Stories'!E:E) | F15: 1 | G15: Backlog | I15: PI-1 (Jan-Mar 2025) | J15: S5
A16: E-06 | B16: F-06.2 | C16: Wizard de configuration club | D16: =COUNTIF('User Stories'!B:B,B16) | E16: =SUMIF('User Stories'!B:B,B16,'User Stories'!E:E) | F16: 1 | G16: Backlog | I16: PI-1 (Jan-Mar 2025) | J16: S6
A17: E-07 | B17: F-07.1 | C17: Cache local étendu (48h) | D17: =COUNTIF('User Stories'!B:B,B17) | E17: =SUMIF('User Stories'!B:B,B17,'User Stories'!E:E) | F17: 1 | G17: Terminé | I17: PI-1 (Jan-Mar 2025) | J17: S4
... A29: E-16 | B29: F-16.1 | C29: Envoi automatique mensuel | D29: =COUNTIF('User Stories'!B:B,B29) | E29: =SUMIF('User Stories'!B:B,B29,'User Stories'!E:E) | F29: 1 | G29: Backlog | I29: PI-1 (Jan-Mar 2025) | J29: S6
A30: PI-2 (Avr-Jun 2025)
A31: E-02 | B31: F-02.2 | C31: Configuration rotation par gymnase | D31: =COUNTIF('User Stories'!B:B,B31) | E31: =SUMIF('User Stories'!B:B,B31,'User Stories'!E:E) | F31: 2 | G31: Backlog | I31: PI-2 (Avr-Jun 2025)
A32: E-03 | B32: F-03.3 | C32: Heatmap de diffusion | D32: =COUNTIF('User Stories'!B:B,B32) | E32: =SUMIF('User Stories'!B:B,B32,'User Stories'!E:E) | F32: 2 | G32: Backlog | I32: PI-2 (Avr-Jun 2025)
A33: E-05 | B33: F-05.2 | C33: Upload d'animations custom (Lottie/MP4) | D33: =COUNTIF('User Stories'!B:B,B33) | E33: =SUMIF('User Stories'!B:B,B33,'User Stories'!E:E) | F33: 2 | G33: Backlog | I33: PI-2 (Avr-Jun 2025)
A34: E-07 | B34: F-07.3 | C34: Support clé USB WiFi externe | D34: =COUNTIF('User Stories'!B:B,B34) | E34: =SUMIF('User Stories'!B:B,B34,'User Stories'!E:E) | F34: 2 | G34: Backlog | I34: PI-2 (Avr-Jun 2025)
A35: E-14 | B35: F-14.1 | C35: Gestion du fonds | D35: =COUNTIF('User Stories'!B:B,B35) | E35: =SUMIF('User Stories'!B:B,B35,'User Stories'!E:E) | F35: 2 | G35: Backlog | I35: PI-2 (Avr-Jun 2025)
A36: E-15 | B36: F-15.1 | C36: Intégration API fédérations sportives | D36: =COUNTIF('User Stories'!B:B,B36) | E36: =SUMIF('User Stories'!B:B,B36,'User Stories'!E:E) | F36: 4 | G36: Hold | I36: PI-2 (Avr-Jun 2025)
A37: E-15 | B37: F-15.2 | C37: Lecture directe table de marque multi-constructeurs (Stramatel, Bodet, OCR) | D37: =COUNTIF('User Stories'!B:B,B37) | E37: =SUMIF('User Stories'!B:B,B37,'User Stories'!E:E) | F37: 1 | G37: Backlog | I37: PI-2 (Avr-Mai 2026)
A38: E-17 | B38: F-17.1 | C38: Campagnes A/B Test | D38: =COUNTIF('User Stories'!B:B,B38) | E38: =SUMIF('User Stories'!B:B,B38,'User Stories'!E:E) | F38: 2 | G38: Backlog | I38: PI-2 (Avr-Jun 2025)
A39: E-18 | B39: F-18.1 | C39: Audience réelle via billetterie | D39: =COUNTIF('User Stories'!B:B,B39) | E39: =SUMIF('User Stories'!B:B,B39,'User Stories'!E:E) | F39: 2 | G39: Backlog | I39: PI-2 (Avr-Jun 2025)
A40: E-19 | B40: F-19.1 | C40: Comptage spectateurs automatique | D40: =COUNTIF('User Stories'!B:B,B40) | E40: =SUMIF('User Stories'!B:B,B40,'User Stories'!E:E) | F40: 3 | G40: Backlog | I40: PI-2 (Avr-Jun 2025)
A41: E-20 | B41: F-20.1 | C41: Prédictions engagement et uptime | D41: =COUNTIF('User Stories'!B:B,B41) | E41: =SUMIF('User Stories'!B:B,B41,'User Stories'!E:E) | F41: 3 | G41: Backlog | I41: PI-2 (Avr-Jun 2025)
A42: E-21 | B42: F-21.1 | C42: API OAuth 2.0 pour partenaires | D42: =COUNTIF('User Stories'!B:B,B42) | E42: =SUMIF('User Stories'!B:B,B42,'User Stories'!E:E) | F42: 3 | G42: Backlog | I42: PI-2 (Avr-Jun 2025)
... A47: E-22 | B47: F-22.3 | C47: Variantes vidéo par type d'écran | D47: =COUNTIF('User Stories'!B:B,B47) | E47: =SUMIF('User Stories'!B:B,B47,'User Stories'!E:E) | F47: 2 | G47: Backlog | I47: PI-2 (Avr-Jun 2026)
A49: SUMMARY
A50: PI | B50: Features | C50: Total SP | D50: Terminé | E50: Backlog
A51: PI-1 (Jan-Mar 2025) | B51: =COUNTIF(I6:I29,"PI-1*") | C51: =SUMIF(I6:I29,"PI-1*",E6:E29) | D51: =COUNTIFS(I6:I29,"PI-1*",G6:G29,"Terminé") | E51: =COUNTIFS(I6:I29,"PI-1*",G6:G29,"Backlog")
A52: PI-2 (Avr-Jun 2025) | B52: =COUNTIF(I31:I47,"PI-2*") | C52: =SUMIF(I31:I47,"PI-2*",E31:E47) | D52: =COUNTIFS(I31:I47,"PI-2*",G31:G47,"Terminé") | E52: =COUNTIFS(I31:I47,"PI-2*",G31:G47,"Backlog")
A53: PI-3 (Jul-Sep 2025) | B53: 0 | C53: 0 | D53: 0 | E53: 0

Sheet PI Objectives
A1: ← Dashboard | B1: ← Dashboard
A3: OBJECTIFS PI
A4: Objectif | B4: Type | C4: Description | D4: Valeur Métier | E4: Statut | F4: Notes / Features | G4: PI
A5: PI-1 (Jan-Mar 2025)
A6: O-PI1-1 | B6: Engagé | C6: Lancer le portail sponsor self-service | D6: 9 | E6: À faire | F6: E-01: F-01.1, F-01.2, F-01.3 | G6: PI-1
A7: O-PI1-2 | B7: Engagé | C7: Livrer les analytics sponsors avec rapport PDF | D7: 10 | E7: À faire | F7: E-03: F-03.1, F-03.2, F-03.3 | G7: PI-1
A8: O-PI1-3 | B8: Engagé | C8: Implémenter la rotation sponsor équitable | D8: 8 | E8: À faire | F8: E-02: F-02.1, F-02.2 | G8: PI-1
A9: O-PI1-4 | B9: Engagé | C9: Créer le wizard onboarding club | D9: 10 | E9: À faire | F9: E-06: F-06.1, F-06.2 | G9: PI-1
A10: O-PI1-5 | B10: Étendu | C10: Carte de la flotte Leaflet | D10: 4 | E10: À faire | F10: E-10: F-10.1 | G10: PI-1
A11: PI-2 (Avr-Jun 2025)
A12: O-PI2-1 | B12: Étendu | C12: Support clé USB WiFi externe | D12: 3 | E12: À faire | F12: E-07: F-07.3 | G12: PI-2
A13: O-PI2-2 | B13: Étendu | C13: Diffusion dynamique de publicités | D13: 8 | E13: En cours | F13: E-11: F-11.1, F-11.2 | G13: PI-2
A14: O-PI2-3 | B14: Étendu | C14: Plateforme d'email marketing | D14: 7 | E14: À faire | F14: E-15: F-15.1 | G14: PI-2
A15: O-PI2-4 | B15: Étendu | C15: Scoring influenceurs prêt | D15: 6 | E15: À faire | F15: E-16: F-16.1 + E-17: F-17.1 | G15: PI-2
A16: ASPIRATIONNEL (Non planifiés)
A17: O-STR-1 | B17: Aspirationnel | C17: Analytics avancés ML | D17: 4 | E17: À faire | F17: — | G17: —
A18: O-STR-2 | B18: Aspirationnel | C18: Ébauche expansion internationale | D18: 3 | E18: À faire | F18: — | G18: —
A20: RÉSUMÉ
A21: PI | B21: BV Engagé | C21: BV Étendu | D21: BV Aspirationnel | E21: BV Total | F21: Obj. Terminés | G21: Prédictabilité %
A22: PI-1 | B22: =SUMIFS(D6:D18,B6:B18,"Engagé",G6:G18,"PI-1") | C22: =SUMIFS(D6:D18,B6:B18,"Étendu",G6:G18,"PI-1") | D22: =SUMIFS(D17:D18,B17:B18,"Aspirationnel") | E22: =SUM(B22:D22) | F22: =COUNTIFS(G6:G10,"PI-1",E6:E10,"Terminé") | G22: =IFERROR(F22/COUNTA(A6:A10),0)
A23: PI-2 | B23: =SUMIFS(D6:D18,B6:B18,"Engagé",G6:G18,"PI-2") | C23: =SUMIFS(D6:D18,B6:B18,"Étendu",G6:G18,"PI-2") | D23: 0 | E23: =SUM(B23:D23) | F23: =COUNTIFS(G12:G15,"PI-2",E12:E15,"Terminé") | G23: =IFERROR(F23/COUNTA(A12:A15),0)
A24: Total | B24: =SUM(B22:B23) | C24: =SUM(C22:C23) | D24: =SUM(D22:D23) | E24: =SUM(E22:E23) | F24: =SUM(F22:F23) | G24: =IFERROR(F24/COUNTA(A6:A18),0)

Sheet Sprint Tracker
A1: ← Dashboard | B1: ← Dashboard
A3: SUIVI DES SPRINTS
A4: Sprint | B4: PI | C4: SP Planifiés | D4: SP Réalisés | E4: Bugs | F4: Vélocité | G4: Notes
A5: PI-1 (Jan-Mar 2025)
A6: S1 | B6: PI-1 | C6: =SUMIF('Features & US'!J:J,"S1",'Features & US'!E:E) | D6: 24 | E6: 3 | F6: =IF(D6="","",D6) | G6: Premier sprint, onboarding
A7: S2 | B7: PI-1 | C7: =SUMIF('Features & US'!J:J,"S2",'Features & US'!E:E) | D7: 27 | E7: 0 | F7: =IF(D7="","",D7) | G7: Vélocité maximale
A8: S3 | B8: PI-1 | C8: =SUMIF('Features & US'!J:J,"S3",'Features & US'!E:E) | D8: 25 | E8: 0 | F8: =IF(D8="","",D8) | G8: Performance stable
A9: S4 | B9: PI-1 | C9: =SUMIF('Features & US'!J:J,"S4",'Features & US'!E:E) | D9: 25 | E9: 0 | F9: =IF(D9="","",D9) | G9: Performance stable
A10: S5 | B10: PI-1 | C10: =SUMIF('Features & US'!J:J,"S5",'Features & US'!E:E) | F10: =IF(D10="","",D10)
A11: S6 | B11: PI-1 | C11: =SUMIF('Features & US'!J:J,"S6",'Features & US'!E:E) | F11: =IF(D11="","",D11)
A12: PI-2 (Avr-Jun 2025)
A13: S7 | B13: PI-2 | C13: =SUMIF('Features & US'!J:J,"S7",'Features & US'!E:E) | F13: =IF(D13="","",D13)
A14: S8 | B14: PI-2 | C14: =SUMIF('Features & US'!J:J,"S8",'Features & US'!E:E) | F14: =IF(D14="","",D14)
A15: S9 | B15: PI-2 | C15: =SUMIF('Features & US'!J:J,"S9",'Features & US'!E:E) | F15: =IF(D15="","",D15)
A16: S10 | B16: PI-2 | C16: =SUMIF('Features & US'!J:J,"S10",'Features & US'!E:E) | F16: =IF(D16="","",D16)
A17: S11 | B17: PI-2 | C17: =SUMIF('Features & US'!J:J,"S11",'Features & US'!E:E) | F17: =IF(D17="","",D17)
A18: S12 | B18: PI-2 | C18: =SUMIF('Features & US'!J:J,"S12",'Features & US'!E:E) | F18: =IF(D18="","",D18)
A20: RÉSUMÉ
A21: PI | B21: Sprints terminés | C21: SP Planifiés | D21: SP Réalisés | E21: Total Bugs | F21: Vélocité moy. | G21: Engagement %
A22: PI-1 | B22: =COUNTA(D6:D11) | C22: =SUM(C6:C11) | D22: =SUM(D6:D11) | E22: =SUM(E6:E11) | F22: =IFERROR(AVERAGE(F6:F11),0) | G22: =IFERROR(D22/C22,0)
A23: PI-2 | B23: =COUNTA(D13:D18) | C23: =SUM(C13:C18) | D23: =SUM(D13:D18) | E23: =SUM(E13:E18) | F23: =IFERROR(AVERAGE(F13:F18),0) | G23: =IFERROR(D23/C23,0)
A24: Total | B24: =SUM(B22:B23) | C24: =SUM(C22:C23) | D24: =SUM(D22:D23) | E24: =SUM(E22:E23) | F24: =IFERROR(AVERAGE(F22:F23),0) | G24: =IFERROR(D24/C24,0)
A26: CAPACITÉ DE L'ÉQUIPE
A27: Membre | B27: Rôle | C27: Capacité (SP/sprint) | D27: Spécialité
A28: Dev Lead | C28: 8 | D28: Backend / Architecture
A29: Frontend Dev | C29: 7 | D29: UI / Angular
A30: Full Stack Dev | C30: 8 | D30: Fonctionnalités
A31: QA Engineer | C31: 4 | D31: Tests / Qualité
A32: Total | C32: =SUM(C28:C31)

Sheet ROAM
A1: ← Dashboard | B1: ← Dashboard
A3: REGISTRE ROAM
A4: ID Risque | B4: Description | C4: Statut ROAM | D4: Probabilité | E4: Impact | F4: Responsable | G4: Échéance | H4: Action / Atténuation
A5: R-01 | B5: Capacité solo-dev insuffisante pour 81 SP engagés | C5: Accepté | D5: Haute | E5: Moyen | F5: Gwenvael
A6: R-02 | B6: WiFi gymnase instable pendant les tests | C6: Atténué | D6: Haute | E6: Moyen | F6: Gwenvael
A7: R-03 | B7: Aucun sponsor inscrit pour valider le portail | C7: Pris en charge | D7: Moyenne | E7: Élevé | F7: Gwenvael + Gabin
A8: R-04 | B8: Dépendance Supabase pour le scaling | C8: Accepté | D8: Basse | E8: Élevé | F8: Gwenvael
A9: R-05 | B9: Sécurité des api_keys Pi | C9: Atténué | D9: Basse | E9: Critique | F9: Gwenvael
A10: R-06 | B10: Retard onboarding automatisé bloque le scaling | C10: Pris en charge | D10: Moyenne | E10: Critique | F10: Gwenvael
A11: R-07 | B11: Hébergement FTP Hostinger comme point de défaillance | C11: Accepté | D11: Basse | E11: Élevé | F11: Gwenvael
A12: R-08 | B12: Absence de tests E2E sur le parcours sponsor | C12: Pris en charge | D12: Haute | E12: Moyen | F12: Gwenvael
A14: RÉSUMÉ ROAM
A15: Statut ROAM | B15: Nombre | C15: % du Total | D15: Couleur | F15: Niveau Impact | G15: Nombre | H15: % du Total
A16: Résolu | B16: =COUNTIF(C5:C12,"Résolu") | C16: =IFERROR(B16/B20,0) | D16: █ Vert | F16: Critique | G16: =COUNTIF(E5:E12,"Critique") | H16: =IFERROR(G16/G19,0)
A17: Pris en charge | B17: =COUNTIF(C5:C12,"Pris en charge") | C17: =IFERROR(B17/B20,0) | D17: █ Orange | F17: Élevé | G17: =COUNTIF(E5:E12,"Élevé") | H17: =IFERROR(G17/G19,0)
A18: Accepté | B18: =COUNTIF(C5:C12,"Accepté") | C18: =IFERROR(B18/B20,0) | D18: █ Jaune | F18: Moyen | G18: =COUNTIF(E5:E12,"Moyen") | H18: =IFERROR(G18/G19,0)
A19: Atténué | B19: =COUNTIF(C5:C12,"Atténué") | C19: =IFERROR(B19/B20,0) | D19: █ Bleu | F19: TOTAL | G19: =SUM(G16:G18) | H19: =SUM(H16:H18)
A20: TOTAL | B20: =SUM(B16:B19) | C20: =SUM(C16:C19)

Sheet Flow Metrics
A1: ← Dashboard | B1: ← Dashboard
A3: MÉTRIQUES DE FLUX PAR VALUE STREAM
A4: Value Stream | B4: Limite TEP | C4: Débit (US/sem.) | D4: Temps de Cycle (jours) | E4: Santé du Flux
A5: OVS-1 : Club to Screen
A6: OVS-2 : Sponsor Impression
A7: DVS-1 : Platform
A8: Support / Dette technique
A9: Intégration / Infra
A10: Apprentissage / Innovation
A11: TOTAL / MOYENNE | B11: =SUM(B5:B10) | C11: =AVERAGE(C5:C10) | D11: =AVERAGE(D5:D10)
A13: ALLOCATION PAR VALUE STREAM
A14: Value Stream | B14: Allocation % | C14: Barre visuelle
A15: Club to Screen | C15: =REPT("█",B15/5)
A16: Sponsor Impression | C16: =REPT("█",B16/5)
A17: Platform Core | C17: =REPT("█",B17/5)
A18: Support / Dette | C18: =REPT("█",B18/5)
A19: Apprentissage | C19: =REPT("█",B19/5)
A20: TOTAL | B20: =SUM(B15:B19)

Sheet Implemented Backlog
A1: ← Dashboard | B1: ← Dashboard
A2: 184 features — 13 domaines — Source: implemented-backlog-import.csv
A3: ID | B3: Feature | C3: Status | D3: Version | E3: Fichier | F3: Domaine
A4: Authentification JWT (HttpOnly cookies + Bearer) | B4: IMP-SEC-01 | C4: Authentification & Sécurité | D4: Production | E4: auth.controller.ts, authentication.service.ts | F4: Déc 2025
A5: MFA / 2FA (TOTP avec QR code) | B5: IMP-SEC-02 | C5: Authentification & Sécurité | D5: Production | E5: mfa.service.ts, mfa.routes.ts | F5: Déc 2025
A6: Réinitialisation mot de passe (token 24h + email) | B6: IMP-SEC-03 | C6: Authentification & Sécurité | D6: Production | E6: password-reset.service.ts | F6: Déc 2025
A7: Journalisation d'audit GDPR | B7: IMP-SEC-04 | C7: Authentification & Sécurité | D7: Production | E7: audit.service.ts, audit.routes.ts | F7: Déc 2025
A8: Sécurité niveau ligne (isolation multi-tenant PostgreSQL) | B8: IMP-SEC-05 | C8: Authentification & Sécurité | D8: Production | E8: 00-create-rls-functions.sql, enable-row-level-security.sql | F8: Déc 2025
A9: CORS fermé par défaut en production | B9: IMP-SEC-06 | C9: Authentification & Sécurité | D9: Production | E9: server.ts | F9: Déc 2025
A10: Auth admin Raspberry (cookies session + mot de passe initial) | B10: IMP-SEC-07 | C10: Authentification & Sécurité | D10: Production | E10: admin-server.js, auth-config.json | F10: Déc 2025
A11: Suppression mot de passe en dur | B11: IMP-SEC-08 | C11: Authentification & Sécurité | D11: Production | E11: - | F11: Déc 2025
A12: GDPR self-service (Art. 17 droit à l'effacement + Art. 20 portabilité) | B12: IMP-SEC-09 | C12: Authentification & Sécurité | D12: Production | E12: gdpr.service.ts | F12: Déc 2025
A13: Sauvegardes chiffrées AES-256-GCM avec PBKDF2 | B13: IMP-SEC-10 | C13: Authentification & Sécurité | D13: Production | E13: backup-encryption.service.ts | F13: Déc 2025
A14: Helmet renforcé (CSP + X-Frame-Options deny + HSTS 1 an) | B14: IMP-SEC-11 | C14: Authentification & Sécurité | D14: Production | E14: server.ts | F14: Déc 2025
... A179: Documentation framework SAFe complète | B179: IMP-DOC-07 | C179: Documentation & Qualité | D179: Production | E179: docs/safe/ | F179: Fév 2026
A181: Statistiques Produit
A182: Features implémentées | B182: 184
A183: Domaines fonctionnels
A184: Controllers API | B184: 38
A185: Services métier | B185: 37
A186: Repositories | B186: 24
A187: Versions released | B187: 30+ (v1.0 → v3.60.0)
A188: Tests (total) | B188: 2 235
A190: ← Dashboard | B190: ← Features & US
A192: DOMAIN SUMMARY
A193: Domaine | B193: Nombre
A194: Authentification & Sécurité | B194: =COUNTIF(F:F,"Authentification & Sécurité")
A195: Clubs & Gestion des sites | B195: =COUNTIF(F:F,"Clubs & Gestion des sites")
A196: Diffusion & Playlists | B196: =COUNTIF(F:F,"Diffusion & Playlists")
A197: Content Management | B197: =COUNTIF(F:F,"Content Management")
A198: Analytics & Reporting | B198: =COUNTIF(F:F,"Analytics & Reporting")
A199: Sponsors & Régie | B199: =COUNTIF(F:F,"Sponsors & Régie")
A200: Mobile & Télécommande | B200: =COUNTIF(F:F,"Mobile & Télécommande")
A201: Infrastructure & Monitoring | B201: =COUNTIF(F:F,"Infrastructure & Monitoring")
A202: Admin & Configuration | B202: =COUNTIF(F:F,"Admin & Configuration")
A203: API & Intégrations | B203: =COUNTIF(F:F,"API & Intégrations")
A204: Notifications | B204: =COUNTIF(F:F,"Notifications")
A205: Performance & Scalabilité | B205: =COUNTIF(F:F,"Performance & Scalabilité")
A206: DevOps & Déploiement | B206: =COUNTIF(F:F,"DevOps & Déploiement")
A207: TOTAL | B207: =SUM(B194:B206)

Sheet User Stories
A1: ← Dashboard | B1: ← Features & US
A3: USER STORIES BACKLOG
A4: US ID | B4: Feature ID | C4: Epic ID | D4: User Story | E4: Story Points | F4: Statut | G4: Sprint | H4: Critères d'acceptation

Sheet _ChartData
A1: Statut | B1: Epics
A2: En cours | B2: =COUNTIF('Epics & LBC'!G:G,"En cours")
A3: Terminé | B3: =COUNTIF('Epics & LBC'!G:G,"Terminé")
A4: Backlog | B4: =COUNTIF('Epics & LBC'!G:G,"Backlog")
A6: PI | B6: Story Points
A7: PI-1 | B7: =SUMIF('Features & US'!I:I,"PI-1*",'Features & US'!E:E)
A8: PI-2 | B8: =SUMIF('Features & US'!I:I,"PI-2*",'Features & US'!E:E)
A9: PI-3 | B9: =SUMIF('Features & US'!I:I,"PI-3*",'Features & US'!E:E)
A11: Sprint | B11: Actual SP
A12: S1 | B12: ='Sprint Tracker'!D6
A13: S2 | B13: ='Sprint Tracker'!D7
A14: S3 | B14: ='Sprint Tracker'!D8
A15: S4 | B15: ='Sprint Tracker'!D9
A17: Domaine | B17: Allocation
A18: Monétisation | B18: 40
A19: Exp. Match | B19: 25
A20: Acquisition | B20: 20
A21: Excellence Ops | B21: 15
